Workbook

Sheet 实例对比
A1: TSP 求解器逐实例策略对比
A2: 数据源：docs/comparison-cache.json；时间统一为秒；Expanded 为展开节点数。MST 相对 07_14_deg Δ% = MST 时间 / 07_14_deg 时间 − 1；HKMST 相对 Concorde Δ% = HKMST 时间 / Concorde 时间 − 1。负值表示目标版本更快；“超时”和“缺失”均不以 0 代替。
A4: 实例 | B4: n | C4: 数据集 | D4: 最优成本 | E4: Concorde | G4: 07_14_deg tsp_bb_26_07_14_deg | J4: MST tsp_bb_07-26-MST | N4: HKMST tsp_bb_07-26-HKMST
E5: 状态 | F5: 时间 (s) | G5: 状态 | H5: 时间 (s) | I5: Expanded | J5: 状态 | K5: 时间 (s) | L5: 相对 07_14_deg Δ% | M5: Expanded | N5: 状态 | O5: 时间 (s) | P5: 相对 Concorde Δ% | Q5: Expanded
A6: burma14 | B6: 14 | C6: TSPLIB | D6: 3323 | E6: 完成 | F6: 0.023716599 | G6: 完成 | H6: 0.033712024 | I6: 4582 | J6: 完成 | K6: 0.022139076 | L6: =IF(OR(K6="",H6=""),"",K6/H6-1) -> -0.34328843 | M6: 3889 | N6: 完成 | O6: 0.013053726 | P6: =IF(OR(O6="",F6=""),"",O6/F6-1) -> -0.44959534 | Q6: 0
A7: ulysses16 | B7: 16 | C7: TSPLIB | D7: 6859 | E7: 完成 | F7: 0.044902779 | G7: 完成 | H7: 16.253642 | I7: 3883908 | J7: 完成 | K7: 5.9922635 | L7: =IF(OR(K7="",H7=""),"",K7/H7-1) -> -0.63132794 | M7: 3294071 | N7: 完成 | O7: 0.015350319 | P7: =IF(OR(O7="",F7=""),"",O7/F7-1) -> -0.65814322 | Q7: 0
A8: gr17 | B8: 17 | C8: TSPLIB | D8: 2085 | E8: 完成 | F8: 0.027278131 | G8: 完成 | H8: 2.9429296 | I8: 463820 | J8: 完成 | K8: 0.78058515 | L8: =IF(OR(K8="",H8=""),"",K8/H8-1) -> -0.73475916 | M8: 396116 | N8: 完成 | O8: 0.0085487943 | P8: =IF(OR(O8="",F8=""),"",O8/F8-1) -> -0.6866063 | Q8: 0
A9: gr21 | B9: 21 | C9: TSPLIB | D9: 2707 | E9: 完成 | F9: 0.013780676 | G9: 完成 | H9: 0.10198983 | I9: 11193 | J9: 完成 | K9: 0.034435205 | L9: =IF(OR(K9="",H9=""),"",K9/H9-1) -> -0.66236627 | M9: 8885 | N9: 完成 | O9: 0.012236789 | P9: =IF(OR(O9="",F9=""),"",O9/F9-1) -> -0.11203275 | Q9: 0
A10: gr24 | B10: 24 | C10: TSPLIB | D10: 1272 | E10: 完成 | F10: 0.018131683 | G10: 完成 | H10: 1.2885453 | I10: 158396 | J10: 完成 | K10: 0.30516747 | L10: =IF(OR(K10="",H10=""),"",K10/H10-1) -> -0.76316901 | M10: 127733 | N10: 完成 | O10: 0.015574662 | P10: =IF(OR(O10="",F10=""),"",O10/F10-1) -> -0.141025 | Q10: 0
A11: fri26 | B11: 26 | C11: TSPLIB | D11: 937 | E11: 完成 | F11: 0.027399978 | G11: 完成 | H11: 2.1436277 | I11: 265361 | J11: 完成 | K11: 0.52409424 | L11: =IF(OR(K11="",H11=""),"",K11/H11-1) -> -0.75551061 | M11: 210001 | N11: 完成 | O11: 0.019281518 | P11: =IF(OR(O11="",F11=""),"",O11/F11-1) -> -0.2962944 | Q11: 0
A12: bayg29 | B12: 29 | C12: TSPLIB | D12: 1610 | E12: 完成 | F12: 0.017626408 | G12: 完成 | H12: 38.601546 | I12: 3624699 | J12: 完成 | K12: 6.9469463 | L12: =IF(OR(K12="",H12=""),"",K12/H12-1) -> -0.8200345 | M12: 2894751 | N12: 完成 | O12: 0.015998486 | P12: =IF(OR(O12="",F12=""),"",O12/F12-1) -> -0.092356991 | Q12: 3
A13: bays29 | B13: 29 | C13: TSPLIB | D13: 2020 | E13: 完成 | F13: 0.033105258 | G13: 完成 | H13: 487.53958 | I13: 43913157 | J13: 完成 | K13: 90.065429 | L13: =IF(OR(K13="",H13=""),"",K13/H13-1) -> -0.8152654 | M13: 35485849 | N13: 完成 | O13: 0.017220551 | P13: =IF(OR(O13="",F13=""),"",O13/F13-1) -> -0.47982429 | Q13: 11
A14: wi29 | B14: 29 | C14: National TSP | D14: 27603 | E14: 完成 | F14: 0.046140678 | G14: 完成 | H14: 0.23881567 | I14: 22343 | J14: 完成 | K14: 0.064899452 | L14: =IF(OR(K14="",H14=""),"",K14/H14-1) -> -0.72824458 | M14: 16378 | N14: 完成 | O14: 0.013915814 | P14: =IF(OR(O14="",F14=""),"",O14/F14-1) -> -0.69840464 | Q14: 0
A15: dj38 | B15: 38 | C15: National TSP | D15: 6656 | E15: 完成 | F15: 0.029789548 | G15: 完成 | H15: 0.12762615 | I15: 7977 | J15: 完成 | K15: 0.031196376 | L15: =IF(OR(K15="",H15=""),"",K15/H15-1) -> -0.75556439 | M15: 5577 | N15: 完成 | O15: 0.013605909 | P15: =IF(OR(O15="",F15=""),"",O15/F15-1) -> -0.54326567 | Q15: 0
A16: dantzig42 | B16: 42 | C16: TSPLIB | D16: 699 | E16: 完成 | F16: 0.042063843 | G16: 超时 | J16: 超时 | L16: =IF(OR(K16="",H16=""),"",K16/H16-1) | N16: 完成 | O16: 0.023938 | P16: =IF(OR(O16="",F16=""),"",O16/F16-1) -> -0.43091267 | Q16: 6
A17: swiss42 | B17: 42 | C17: TSPLIB | D17: 1273 | E17: 完成 | F17: 0.028670536 | G17: 超时 | J17: 完成 | K17: 932.67663 | L17: =IF(OR(K17="",H17=""),"",K17/H17-1) | M17: 295900192 | N17: 完成 | O17: 0.01309151 | P17: =IF(OR(O17="",F17=""),"",O17/F17-1) -> -0.54338105 | Q17: 4
A18: att48 | B18: 48 | C18: TSPLIB | D18: 10628 | E18: 完成 | F18: 0.078497818 | G18: 超时 | J18: 超时 | L18: =IF(OR(K18="",H18=""),"",K18/H18-1) | N18: 完成 | O18: 0.032715769 | P18: =IF(OR(O18="",F18=""),"",O18/F18-1) -> -0.58322702 | Q18: 281
A19: gr48 | B19: 48 | C19: TSPLIB | D19: 5046 | E19: 完成 | F19: 0.095788699 | G19: 超时 | J19: 超时 | L19: =IF(OR(K19="",H19=""),"",K19/H19-1) | N19: 完成 | O19: 0.2663761 | P19: =IF(OR(O19="",F19=""),"",O19/F19-1) -> 1.7808719 | Q19: 90001
A20: hk48 | B20: 48 | C20: TSPLIB | D20: 11461 | E20: 完成 | F20: 0.032694919 | G20: 超时 | J20: 完成 | K20: 517.54384 | L20: =IF(OR(K20="",H20=""),"",K20/H20-1) | M20: 137410226 | N20: 完成 | O20: 0.026482055 | P20: =IF(OR(O20="",F20=""),"",O20/F20-1) -> -0.19002537 | Q20: 36
A21: eil51 | B21: 51 | C21: TSPLIB | D21: 426 | E21: 完成 | F21: 0.047876732 | G21: 超时 | J21: 缺失 | L21: =IF(OR(K21="",H21=""),"",K21/H21-1) | N21: 完成 | O21: 0.081606746 | P21: =IF(OR(O21="",F21=""),"",O21/F21-1) -> 0.70451786 | Q21: 15848
A22: berlin52 | B22: 52 | C22: TSPLIB | D22: 7542 | E22: 完成 | F22: 0.055544732 | G22: 超时 | J22: 缺失 | L22: =IF(OR(K22="",H22=""),"",K22/H22-1) | N22: 完成 | O22: 0.021707196 | P22: =IF(OR(O22="",F22=""),"",O22/F22-1) -> -0.60919434 | Q22: 0
A23: brazil58 | B23: 58 | C23: TSPLIB | D23: 25395 | E23: 完成 | F23: 0.086955516 | G23: 超时 | J23: 缺失 | L23: =IF(OR(K23="",H23=""),"",K23/H23-1) | N23: 完成 | O23: 0.41811504 | P23: =IF(OR(O23="",F23=""),"",O23/F23-1) -> 3.8083786 | Q23: 112098
A24: st70 | B24: 70 | C24: TSPLIB | D24: 675 | E24: 完成 | F24: 0.065910155 | G24: 缺失 | J24: 缺失 | L24: =IF(OR(K24="",H24=""),"",K24/H24-1) | N24: 完成 | O24: 18.704484 | P24: =IF(OR(O24="",F24=""),"",O24/F24-1) -> 282.78759 | Q24: 5632636
A25: eil76 | B25: 76 | C25: TSPLIB | D25: 538 | E25: 完成 | F25: 0.052238083 | G25: 缺失 | J25: 缺失 | L25: =IF(OR(K25="",H25=""),"",K25/H25-1) | N25: 完成 | O25: 0.58667819 | P25: =IF(OR(O25="",F25=""),"",O25/F25-1) -> 10.230852 | Q25: 105325
A26: pr76 | B26: 76 | C26: TSPLIB | D26: 108159 | E26: 完成 | F26: 0.20861356 | G26: 缺失 | J26: 缺失 | L26: =IF(OR(K26="",H26=""),"",K26/H26-1) | N26: 超时 | P26: =IF(OR(O26="",F26=""),"",O26/F26-1)
A27: gr96 | B27: 96 | C27: TSPLIB | D27: 55209 | E27: 完成 | F27: 0.21235803 | G27: 缺失 | J27: 缺失 | L27: =IF(OR(K27="",H27=""),"",K27/H27-1) | N27: 完成 | O27: 7.9101297 | P27: =IF(OR(O27="",F27=""),"",O27/F27-1) -> 36.249026 | Q27: 1672187
A28: rat99 | B28: 99 | C28: TSPLIB | D28: 1211 | E28: 完成 | F28: 1.1216565 | G28: 缺失 | J28: 缺失 | L28: =IF(OR(K28="",H28=""),"",K28/H28-1) | N28: 完成 | O28: 0.46335986 | P28: =IF(OR(O28="",F28=""),"",O28/F28-1) -> -0.58689682 | Q28: 67911
A29: kroA100 | B29: 100 | C29: TSPLIB | D29: 21282 | E29: 完成 | F29: 0.10308041 | G29: 缺失 | J29: 缺失 | L29: =IF(OR(K29="",H29=""),"",K29/H29-1) | N29: 完成 | O29: 806.30711 | P29: =IF(OR(O29="",F29=""),"",O29/F29-1) -> 7821.1176 | Q29: 146674028
A30: kroB100 | B30: 100 | C30: TSPLIB | D30: 22141 | E30: 完成 | F30: 0.19104896 | G30: 缺失 | J30: 缺失 | L30: =IF(OR(K30="",H30=""),"",K30/H30-1) | N30: 超时 | P30: =IF(OR(O30="",F30=""),"",O30/F30-1)
A31: kroC100 | B31: 100 | C31: TSPLIB | D31: 20749 | E31: 完成 | F31: 0.11491081 | G31: 缺失 | J31: 缺失 | L31: =IF(OR(K31="",H31=""),"",K31/H31-1) | N31: 完成 | O31: 40.040623 | P31: =IF(OR(O31="",F31=""),"",O31/F31-1) -> 347.44958 | Q31: 8463763
A32: kroD100 | B32: 100 | C32: TSPLIB | D32: 21294 | E32: 完成 | F32: 0.14843041 | G32: 缺失 | J32: 缺失 | L32: =IF(OR(K32="",H32=""),"",K32/H32-1) | N32: 完成 | O32: 593.61726 | P32: =IF(OR(O32="",F32=""),"",O32/F32-1) -> 3998.2969 | Q32: 90688415
A33: kroE100 | B33: 100 | C33: TSPLIB | D33: 22068 | E33: 完成 | F33: 0.24577824 | G33: 缺失 | J33: 缺失 | L33: =IF(OR(K33="",H33=""),"",K33/H33-1) | N33: 超时 | P33: =IF(OR(O33="",F33=""),"",O33/F33-1)
A34: rd100 | B34: 100 | C34: TSPLIB | D34: 7910 | E34: 完成 | F34: 0.084279737 | G34: 缺失 | J34: 缺失 | L34: =IF(OR(K34="",H34=""),"",K34/H34-1) | N34: 完成 | O34: 2.0570126 | P34: =IF(OR(O34="",F34=""),"",O34/F34-1) -> 23.406965 | Q34: 350903
A35: eil101 | B35: 101 | C35: TSPLIB | D35: 629 | E35: 完成 | F35: 0.087469727 | G35: 缺失 | J35: 缺失 | L35: =IF(OR(K35="",H35=""),"",K35/H35-1) | N35: 完成 | O35: 12.182773 | P35: =IF(OR(O35="",F35=""),"",O35/F35-1) -> 138.27988 | Q35: 2747059
A36: lin105 | B36: 105 | C36: TSPLIB | D36: 14379 | E36: 完成 | F36: 0.086335123 | G36: 缺失 | J36: 缺失 | L36: =IF(OR(K36="",H36=""),"",K36/H36-1) | N36: 完成 | O36: 0.16162609 | P36: =IF(OR(O36="",F36=""),"",O36/F36-1) -> 0.87207807 | Q36: 225
A37: pr107 | B37: 107 | C37: TSPLIB | D37: 44303 | E37: 完成 | F37: 0.15447498 | G37: 缺失 | J37: 缺失 | L37: =IF(OR(K37="",H37=""),"",K37/H37-1) | N37: 超时 | P37: =IF(OR(O37="",F37=""),"",O37/F37-1)
A38: gr120 | B38: 120 | C38: TSPLIB | D38: 6942 | E38: 完成 | F38: 0.16962153 | G38: 缺失 | J38: 缺失 | L38: =IF(OR(K38="",H38=""),"",K38/H38-1) | N38: 超时 | P38: =IF(OR(O38="",F38=""),"",O38/F38-1)
A39: pr124 | B39: 124 | C39: TSPLIB | D39: 59030 | E39: 完成 | F39: 0.49239663 | G39: 缺失 | J39: 缺失 | L39: =IF(OR(K39="",H39=""),"",K39/H39-1) | N39: 完成 | O39: 4.0410658 | P39: =IF(OR(O39="",F39=""),"",O39/F39-1) -> 7.2069323 | Q39: 487141
A40: bier127 | B40: 127 | C40: TSPLIB | D40: 118282 | E40: 完成 | F40: 0.24913277 | G40: 缺失 | J40: 缺失 | L40: =IF(OR(K40="",H40=""),"",K40/H40-1) | N40: 超时 | P40: =IF(OR(O40="",F40=""),"",O40/F40-1)
A41: ch130 | B41: 130 | C41: TSPLIB | D41: 6110 | E41: 完成 | F41: 0.27886009 | G41: 缺失 | J41: 缺失 | L41: =IF(OR(K41="",H41=""),"",K41/H41-1) | N41: 超时 | P41: =IF(OR(O41="",F41=""),"",O41/F41-1)
...

Sheet HKMST相对基线
A1: 07-26-HKMST 相对 07-26-MST 与 Concorde 的逐实例变化
A2: E:J 对比 HKMST 与 07-26-MST 的耗时和 Expanded；K:P 对比 HKMST 与 Concorde 的耗时与完成状态。Δ% = HKMST / 基准 − 1；负值表示 HKMST 更快。Concorde 的 branch-and-cut 节点与 tsp_bb Expanded 口径不同，不作节点 Δ% 比较。
A4: 实例 | B4: n | C4: 数据集 | D4: 最优成本 | E4: 07-26-HKMST vs 07-26-MST tsp_bb_07-26-HKMST / tsp_bb_07-26-MST | K4: 07-26-HKMST vs Concorde tsp_bb_07-26-HKMST / concorde
E5: MST 时间 (s) | F5: HKMST 时间 (s) | G5: 时间 Δ% | H5: MST Expanded | I5: HKMST Expanded | J5: 节点 Δ% | K5: Concorde 时间 (s) | L5: HKMST 时间 (s) | M5: 时间 Δ% | N5: Concorde 状态 | O5: HKMST 状态 | P5: 对比结论
A6: burma14 | B6: 14 | C6: TSPLIB | D6: 3323 | E6: =IF(实例对比!K6="","",实例对比!K6) -> 0.022139076 | F6: =IF(实例对比!O6="","",实例对比!O6) -> 0.013053726 | G6: =IF(OR(F6="",E6=""),"",F6/E6-1) -> -0.41037619 | H6: =IF(实例对比!M6="","",实例对比!M6) -> 3889 | I6: =IF(实例对比!Q6="","",实例对比!Q6) -> 0 | J6: =IF(OR(I6="",H6=""),"",I6/H6-1) -> -1 | K6: =IF(实例对比!F6="","",实例对比!F6) -> 0.023716599 | L6: =IF(实例对比!O6="","",实例对比!O6) -> 0.013053726 | M6: =IF(OR(L6="",K6=""),"",L6/K6-1) -> -0.44959534 | N6: =实例对比!E6 -> 完成 | O6: =实例对比!N6 -> 完成 | P6: =IF(AND(N6="完成",O6="完成"),IF(M6<0,"HKMST 更快",IF(M6>0,"Concorde 更快","相同")),"不可比") -> HKMST 更快
A7: ulysses16 | B7: 16 | C7: TSPLIB | D7: 6859 | E7: =IF(实例对比!K7="","",实例对比!K7) -> 5.9922635 | F7: =IF(实例对比!O7="","",实例对比!O7) -> 0.015350319 | G7: =IF(OR(F7="",E7=""),"",F7/E7-1) -> -0.99743831 | H7: =IF(实例对比!M7="","",实例对比!M7) -> 3294071 | I7: =IF(实例对比!Q7="","",实例对比!Q7) -> 0 | J7: =IF(OR(I7="",H7=""),"",I7/H7-1) -> -1 | K7: =IF(实例对比!F7="","",实例对比!F7) -> 0.044902779 | L7: =IF(实例对比!O7="","",实例对比!O7) -> 0.015350319 | M7: =IF(OR(L7="",K7=""),"",L7/K7-1) -> -0.65814322 | N7: =实例对比!E7 -> 完成 | O7: =实例对比!N7 -> 完成 | P7: =IF(AND(N7="完成",O7="完成"),IF(M7<0,"HKMST 更快",IF(M7>0,"Concorde 更快","相同")),"不可比") -> HKMST 更快
A8: gr17 | B8: 17 | C8: TSPLIB | D8: 2085 | E8: =IF(实例对比!K8="","",实例对比!K8) -> 0.78058515 | F8: =IF(实例对比!O8="","",实例对比!O8) -> 0.0085487943 | G8: =IF(OR(F8="",E8=""),"",F8/E8-1) -> -0.98904822 | H8: =IF(实例对比!M8="","",实例对比!M8) -> 396116 | I8: =IF(实例对比!Q8="","",实例对比!Q8) -> 0 | J8: =IF(OR(I8="",H8=""),"",I8/H8-1) -> -1 | K8: =IF(实例对比!F8="","",实例对比!F8) -> 0.027278131 | L8: =IF(实例对比!O8="","",实例对比!O8) -> 0.0085487943 | M8: =IF(OR(L8="",K8=""),"",L8/K8-1) -> -0.6866063 | N8: =实例对比!E8 -> 完成 | O8: =实例对比!N8 -> 完成 | P8: =IF(AND(N8="完成",O8="完成"),IF(M8<0,"HKMST 更快",IF(M8>0,"Concorde 更快","相同")),"不可比") -> HKMST 更快
A9: gr21 | B9: 21 | C9: TSPLIB | D9: 2707 | E9: =IF(实例对比!K9="","",实例对比!K9) -> 0.034435205 | F9: =IF(实例对比!O9="","",实例对比!O9) -> 0.012236789 | G9: =IF(OR(F9="",E9=""),"",F9/E9-1) -> -0.64464307 | H9: =IF(实例对比!M9="","",实例对比!M9) -> 8885 | I9: =IF(实例对比!Q9="","",实例对比!Q9) -> 0 | J9: =IF(OR(I9="",H9=""),"",I9/H9-1) -> -1 | K9: =IF(实例对比!F9="","",实例对比!F9) -> 0.013780676 | L9: =IF(实例对比!O9="","",实例对比!O9) -> 0.012236789 | M9: =IF(OR(L9="",K9=""),"",L9/K9-1) -> -0.11203275 | N9: =实例对比!E9 -> 完成 | O9: =实例对比!N9 -> 完成 | P9: =IF(AND(N9="完成",O9="完成"),IF(M9<0,"HKMST 更快",IF(M9>0,"Concorde 更快","相同")),"不可比") -> HKMST 更快
A10: gr24 | B10: 24 | C10: TSPLIB | D10: 1272 | E10: =IF(实例对比!K10="","",实例对比!K10) -> 0.30516747 | F10: =IF(实例对比!O10="","",实例对比!O10) -> 0.015574662 | G10: =IF(OR(F10="",E10=""),"",F10/E10-1) -> -0.94896356 | H10: =IF(实例对比!M10="","",实例对比!M10) -> 127733 | I10: =IF(实例对比!Q10="","",实例对比!Q10) -> 0 | J10: =IF(OR(I10="",H10=""),"",I10/H10-1) -> -1 | K10: =IF(实例对比!F10="","",实例对比!F10) -> 0.018131683 | L10: =IF(实例对比!O10="","",实例对比!O10) -> 0.015574662 | M10: =IF(OR(L10="",K10=""),"",L10/K10-1) -> -0.141025 | N10: =实例对比!E10 -> 完成 | O10: =实例对比!N10 -> 完成 | P10: =IF(AND(N10="完成",O10="完成"),IF(M10<0,"HKMST 更快",IF(M10>0,"Concorde 更快","相同")),"不可比") -> HKMST 更快
A11: fri26 | B11: 26 | C11: TSPLIB | D11: 937 | E11: =IF(实例对比!K11="","",实例对比!K11) -> 0.52409424 | F11: =IF(实例对比!O11="","",实例对比!O11) -> 0.019281518 | G11: =IF(OR(F11="",E11=""),"",F11/E11-1) -> -0.96320983 | H11: =IF(实例对比!M11="","",实例对比!M11) -> 210001 | I11: =IF(实例对比!Q11="","",实例对比!Q11) -> 0 | J11: =IF(OR(I11="",H11=""),"",I11/H11-1) -> -1 | K11: =IF(实例对比!F11="","",实例对比!F11) -> 0.027399978 | L11: =IF(实例对比!O11="","",实例对比!O11) -> 0.019281518 | M11: =IF(OR(L11="",K11=""),"",L11/K11-1) -> -0.2962944 | N11: =实例对比!E11 -> 完成 | O11: =实例对比!N11 -> 完成 | P11: =IF(AND(N11="完成",O11="完成"),IF(M11<0,"HKMST 更快",IF(M11>0,"Concorde 更快","相同")),"不可比") -> HKMST 更快
A12: bayg29 | B12: 29 | C12: TSPLIB | D12: 1610 | E12: =IF(实例对比!K12="","",实例对比!K12) -> 6.9469463 | F12: =IF(实例对比!O12="","",实例对比!O12) -> 0.015998486 | G12: =IF(OR(F12="",E12=""),"",F12/E12-1) -> -0.99769705 | H12: =IF(实例对比!M12="","",实例对比!M12) -> 2894751 | I12: =IF(实例对比!Q12="","",实例对比!Q12) -> 3 | J12: =IF(OR(I12="",H12=""),"",I12/H12-1) -> -0.99999896 | K12: =IF(实例对比!F12="","",实例对比!F12) -> 0.017626408 | L12: =IF(实例对比!O12="","",实例对比!O12) -> 0.015998486 | M12: =IF(OR(L12="",K12=""),"",L12/K12-1) -> -0.092356991 | N12: =实例对比!E12 -> 完成 | O12: =实例对比!N12 -> 完成 | P12: =IF(AND(N12="完成",O12="完成"),IF(M12<0,"HKMST 更快",IF(M12>0,"Concorde 更快","相同")),"不可比") -> HKMST 更快
A13: bays29 | B13: 29 | C13: TSPLIB | D13: 2020 | E13: =IF(实例对比!K13="","",实例对比!K13) -> 90.065429 | F13: =IF(实例对比!O13="","",实例对比!O13) -> 0.017220551 | G13: =IF(OR(F13="",E13=""),"",F13/E13-1) -> -0.9998088 | H13: =IF(实例对比!M13="","",实例对比!M13) -> 35485849 | I13: =IF(实例对比!Q13="","",实例对比!Q13) -> 11 | J13: =IF(OR(I13="",H13=""),"",I13/H13-1) -> -0.99999969 | K13: =IF(实例对比!F13="","",实例对比!F13) -> 0.033105258 | L13: =IF(实例对比!O13="","",实例对比!O13) -> 0.017220551 | M13: =IF(OR(L13="",K13=""),"",L13/K13-1) -> -0.47982429 | N13: =实例对比!E13 -> 完成 | O13: =实例对比!N13 -> 完成 | P13: =IF(AND(N13="完成",O13="完成"),IF(M13<0,"HKMST 更快",IF(M13>0,"Concorde 更快","相同")),"不可比") -> HKMST 更快
A14: wi29 | B14: 29 | C14: National TSP | D14: 27603 | E14: =IF(实例对比!K14="","",实例对比!K14) -> 0.064899452 | F14: =IF(实例对比!O14="","",实例对比!O14) -> 0.013915814 | G14: =IF(OR(F14="",E14=""),"",F14/E14-1) -> -0.78557886 | H14: =IF(实例对比!M14="","",实例对比!M14) -> 16378 | I14: =IF(实例对比!Q14="","",实例对比!Q14) -> 0 | J14: =IF(OR(I14="",H14=""),"",I14/H14-1) -> -1 | K14: =IF(实例对比!F14="","",实例对比!F14) -> 0.046140678 | L14: =IF(实例对比!O14="","",实例对比!O14) -> 0.013915814 | M14: =IF(OR(L14="",K14=""),"",L14/K14-1) -> -0.69840464 | N14: =实例对比!E14 -> 完成 | O14: =实例对比!N14 -> 完成 | P14: =IF(AND(N14="完成",O14="完成"),IF(M14<0,"HKMST 更快",IF(M14>0,"Concorde 更快","相同")),"不可比") -> HKMST 更快
A15: dj38 | B15: 38 | C15: National TSP | D15: 6656 | E15: =IF(实例对比!K15="","",实例对比!K15) -> 0.031196376 | F15: =IF(实例对比!O15="","",实例对比!O15) -> 0.013605909 | G15: =IF(OR(F15="",E15=""),"",F15/E15-1) -> -0.5638625 | H15: =IF(实例对比!M15="","",实例对比!M15) -> 5577 | I15: =IF(实例对比!Q15="","",实例对比!Q15) -> 0 | J15: =IF(OR(I15="",H15=""),"",I15/H15-1) -> -1 | K15: =IF(实例对比!F15="","",实例对比!F15) -> 0.029789548 | L15: =IF(实例对比!O15="","",实例对比!O15) -> 0.013605909 | M15: =IF(OR(L15="",K15=""),"",L15/K15-1) -> -0.54326567 | N15: =实例对比!E15 -> 完成 | O15: =实例对比!N15 -> 完成 | P15: =IF(AND(N15="完成",O15="完成"),IF(M15<0,"HKMST 更快",IF(M15>0,"Concorde 更快","相同")),"不可比") -> HKMST 更快
A16: dantzig42 | B16: 42 | C16: TSPLIB | D16: 699 | E16: =IF(实例对比!K16="","",实例对比!K16) | F16: =IF(实例对比!O16="","",实例对比!O16) -> 0.023938 | G16: =IF(OR(F16="",E16=""),"",F16/E16-1) | H16: =IF(实例对比!M16="","",实例对比!M16) | I16: =IF(实例对比!Q16="","",实例对比!Q16) -> 6 | J16: =IF(OR(I16="",H16=""),"",I16/H16-1) | K16: =IF(实例对比!F16="","",实例对比!F16) -> 0.042063843 | L16: =IF(实例对比!O16="","",实例对比!O16) -> 0.023938 | M16: =IF(OR(L16="",K16=""),"",L16/K16-1) -> -0.43091267 | N16: =实例对比!E16 -> 完成 | O16: =实例对比!N16 -> 完成 | P16: =IF(AND(N16="完成",O16="完成"),IF(M16<0,"HKMST 更快",IF(M16>0,"Concorde 更快","相同")),"不可比") -> HKMST 更快
A17: swiss42 | B17: 42 | C17: TSPLIB | D17: 1273 | E17: =IF(实例对比!K17="","",实例对比!K17) -> 932.67663 | F17: =IF(实例对比!O17="","",实例对比!O17) -> 0.01309151 | G17: =IF(OR(F17="",E17=""),"",F17/E17-1) -> -0.99998596 | H17: =IF(实例对比!M17="","",实例对比!M17) -> 295900192 | I17: =IF(实例对比!Q17="","",实例对比!Q17) -> 4 | J17: =IF(OR(I17="",H17=""),"",I17/H17-1) -> -0.99999999 | K17: =IF(实例对比!F17="","",实例对比!F17) -> 0.028670536 | L17: =IF(实例对比!O17="","",实例对比!O17) -> 0.01309151 | M17: =IF(OR(L17="",K17=""),"",L17/K17-1) -> -0.54338105 | N17: =实例对比!E17 -> 完成 | O17: =实例对比!N17 -> 完成 | P17: =IF(AND(N17="完成",O17="完成"),IF(M17<0,"HKMST 更快",IF(M17>0,"Concorde 更快","相同")),"不可比") -> HKMST 更快
... A47: kroA150 | B47: 150 | C47: TSPLIB | D47: 26524 | E47: =IF(实例对比!K47="","",实例对比!K47) | F47: =IF(实例对比!O47="","",实例对比!O47) | G47: =IF(OR(F47="",E47=""),"",F47/E47-1) | H47: =IF(实例对比!M47="","",实例对比!M47) | I47: =IF(实例对比!Q47="","",实例对比!Q47) | J47: =IF(OR(I47="",H47=""),"",I47/H47-1) | K47: =IF(实例对比!F47="","",实例对比!F47) -> 0.69183376 | L47: =IF(实例对比!O47="","",实例对比!O47) | M47: =IF(OR(L47="",K47=""),"",L47/K47-1) | N47: =实例对比!E47 -> 完成 | O47: =实例对比!N47 -> 超时 | P47: =IF(AND(N47="完成",O47="完成"),IF(M47<0,"HKMST 更快",IF(M47>0,"Concorde 更快","相同")),"不可比") -> 不可比

Sheet 版本说明
A1: 版本说明、覆盖情况与计算口径
A2: 覆盖统计基于三个 tsp_bb 版本（07_14_deg、07-26-MST、07-26-HKMST）在 comparison-cache.json 中的结果与超时记录并集；Concorde 对同一实例集合提供精确对照。
A3: 显示名称 | B3: 缓存键 | C3: Branch Strategy | D3: Edge Selection | E3: 势 / 下界 | F3: 完成 | G3: 超时 | H3: 缺失
A4: Concorde | B4: concorde | C4: Branch-and-cut | D4: Concorde 内部策略 | E4: LP / cutting planes | F4: =COUNTIF(实例对比!E6:E47,"完成") -> 42 | G4: =COUNTIF(实例对比!E6:E47,"超时") -> 0 | H4: =COUNTIF(实例对比!E6:E47,"缺失") -> 0
A5: 07_14_deg | B5: tsp_bb_26_07_14_deg | C5: BP（multi-child） | D5: 度数违规顶点 + 最便宜树边 | E5: 增量 1-tree | F5: =COUNTIF(实例对比!G6:G47,"完成") -> 10 | G5: =COUNTIF(实例对比!G6:G47,"超时") -> 8 | H5: =COUNTIF(实例对比!G6:G47,"缺失") -> 24
A6: MST | B6: tsp_bb_07-26-MST | C6: BP（07-26 MST） | D6: MST 分支与动态 replacement | E6: MST / 1-tree 下界 | F6: =COUNTIF(实例对比!J6:J47,"完成") -> 12 | G6: =COUNTIF(实例对比!J6:J47,"超时") -> 3 | H6: =COUNTIF(实例对比!J6:J47,"缺失") -> 27
A7: HKMST | B7: tsp_bb_07-26-HKMST | C7: 最大化收益 BP | D7: HK 势更新后进行分支适配 | E7: Held–Karp 势 + 动态 MST | F7: =COUNTIF(实例对比!N6:N47,"完成") -> 30 | G7: =COUNTIF(实例对比!N6:N47,"超时") -> 12 | H7: =COUNTIF(实例对比!N6:N47,"缺失") -> 0
A9: 口径与来源
A10: 数据源 | B10: docs/comparison-cache.json
A11: 实例集合 | B11: 三个 tsp_bb 版本结果/超时记录的并集，共 42 个实例。
A12: Concorde | B12: 缓存顶层 concorde；用于最优成本与精确求解耗时对照。
A13: 耗时 | B13: 直接使用缓存 elapsed，单位为秒；未进行跨机器校准。
A14: Expanded | B14: 直接使用缓存 nodes_expanded，作为分支树规模代理。
A15: Δ% 公式 | B15: “实例对比”页：MST / 07_14_deg − 1，HKMST / Concorde − 1；“HKMST相对基线”页：HKMST / 07-26-MST 或 Concorde − 1。负值表示目标版本更快或展开节点更少。
A16: 超时 | B16: solver_timeouts 为 true，或结果记录 timeout 为 true。
A17: 缺失 | B17: 该版本既没有完成结果，也没有明确超时记录；不以 0 代替。
A18: 成本校验 | B18: 已完成结果与 Concorde 最优成本对比，不一致记录数：0。
A19: 生成日期 | B19: 2026-07-26（Asia/Shanghai）
