Workbook

Sheet 汇总
A1: HKMST 与 NEWHKMST 实验汇总
A2: 提升率=(基准-当前)/基准；正数表示更快或分支更少（绿色），负数表示退化（红色）。时间为完整子进程 wall time；分支数采用 tsp_bb 的 Nodes created。汇总提升率只统计双方均返回Concorde最优值的可比实例。
A3: 算法 | B3: 完成求解 | C3: 与Concorde一致 | D3: 超时 | E3: 错误 | F3: 错误结果 | G3: 总时间(s) | H3: 平均时间(s) | I3: 中位时间(s) | J3: 总节点/分支 | K3: 总展开节点 | L3: 时间提升 vs Concorde | M3: 时间提升 vs HKMST | N3: 分支减少 vs HKMST
A4: Concorde | B4: =COUNTIF('逐实例对比'!$D$4:$D$52,"OPTIMAL")+COUNTIF('逐实例对比'!$D$4:$D$52,"WRONG COST")+COUNTIF('逐实例对比'!$D$4:$D$52,"SOLVED (NO REF)") | C4: =COUNTIF('逐实例对比'!$D$4:$D$52,"OPTIMAL") | D4: =COUNTIF('逐实例对比'!$D$4:$D$52,"TIMEOUT") | E4: =COUNTIF('逐实例对比'!$D$4:$D$52,"ERROR") | F4: =COUNTIF('逐实例对比'!$D$4:$D$52,"WRONG COST") | G4: =SUM('逐实例对比'!$F$4:$F$52) | H4: =IFERROR(AVERAGE('逐实例对比'!$F$4:$F$52),"") | I4: =IFERROR(MEDIAN('逐实例对比'!$F$4:$F$52),"") | J4: =SUM('逐实例对比'!$G$4:$G$52)
A5: HKMST | B5: =COUNTIF('逐实例对比'!$H$4:$H$52,"OPTIMAL")+COUNTIF('逐实例对比'!$H$4:$H$52,"WRONG COST")+COUNTIF('逐实例对比'!$H$4:$H$52,"SOLVED (NO REF)") | C5: =COUNTIF('逐实例对比'!$H$4:$H$52,"OPTIMAL") | D5: =COUNTIF('逐实例对比'!$H$4:$H$52,"TIMEOUT") | E5: =COUNTIF('逐实例对比'!$H$4:$H$52,"ERROR") | F5: =COUNTIF('逐实例对比'!$H$4:$H$52,"WRONG COST") | G5: =SUM('逐实例对比'!$J$4:$J$52) | H5: =IFERROR(AVERAGE('逐实例对比'!$J$4:$J$52),"") | I5: =IFERROR(MEDIAN('逐实例对比'!$J$4:$J$52),"") | J5: =SUM('逐实例对比'!$K$4:$K$52) | K5: =SUM('逐实例对比'!$L$4:$L$52) | L5: =IFERROR((SUMIFS('逐实例对比'!$F$4:$F$52,'逐实例对比'!$D$4:$D$52,"OPTIMAL",'逐实例对比'!$H$4:$H$52,"OPTIMAL")-SUMIFS('逐实例对比'!$J$4:$J$52,'逐实例对比'!$D$4:$D$52,"OPTIMAL",'逐实例对比'!$H$4:$H$52,"OPTIMAL"))/SUMIFS('逐实例对比'!$F$4:$F$52,'逐实例对比'!$D$4:$D$52,"OPTIMAL",'逐实例对比'!$H$4:$H$52,"OPTIMAL"),"")
A6: NEWHKMST | B6: =COUNTIF('逐实例对比'!$N$4:$N$52,"OPTIMAL")+COUNTIF('逐实例对比'!$N$4:$N$52,"WRONG COST")+COUNTIF('逐实例对比'!$N$4:$N$52,"SOLVED (NO REF)") | C6: =COUNTIF('逐实例对比'!$N$4:$N$52,"OPTIMAL") | D6: =COUNTIF('逐实例对比'!$N$4:$N$52,"TIMEOUT") | E6: =COUNTIF('逐实例对比'!$N$4:$N$52,"ERROR") | F6: =COUNTIF('逐实例对比'!$N$4:$N$52,"WRONG COST") | G6: =SUM('逐实例对比'!$P$4:$P$52) | H6: =IFERROR(AVERAGE('逐实例对比'!$P$4:$P$52),"") | I6: =IFERROR(MEDIAN('逐实例对比'!$P$4:$P$52),"") | J6: =SUM('逐实例对比'!$Q$4:$Q$52) | K6: =SUM('逐实例对比'!$R$4:$R$52) | L6: =IFERROR((SUMIFS('逐实例对比'!$F$4:$F$52,'逐实例对比'!$D$4:$D$52,"OPTIMAL",'逐实例对比'!$N$4:$N$52,"OPTIMAL")-SUMIFS('逐实例对比'!$P$4:$P$52,'逐实例对比'!$D$4:$D$52,"OPTIMAL",'逐实例对比'!$N$4:$N$52,"OPTIMAL"))/SUMIFS('逐实例对比'!$F$4:$F$52,'逐实例对比'!$D$4:$D$52,"OPTIMAL",'逐实例对比'!$N$4:$N$52,"OPTIMAL"),"") | M6: =IFERROR((SUMIFS('逐实例对比'!$J$4:$J$52,'逐实例对比'!$H$4:$H$52,"OPTIMAL",'逐实例对比'!$N$4:$N$52,"OPTIMAL")-SUMIFS('逐实例对比'!$P$4:$P$52,'逐实例对比'!$H$4:$H$52,"OPTIMAL",'逐实例对比'!$N$4:$N$52,"OPTIMAL"))/SUMIFS('逐实例对比'!$J$4:$J$52,'逐实例对比'!$H$4:$H$52,"OPTIMAL",'逐实例对比'!$N$4:$N$52,"OPTIMAL"),"") | N6: =IFERROR((SUMIFS('逐实例对比'!$K$4:$K$52,'逐实例对比'!$H$4:$H$52,"OPTIMAL",'逐实例对比'!$N$4:$N$52,"OPTIMAL")-SUMIFS('逐实例对比'!$Q$4:$Q$52,'逐实例对比'!$H$4:$H$52,"OPTIMAL",'逐实例对比'!$N$4:$N$52,"OPTIMAL"))/SUMIFS('逐实例对比'!$K$4:$K$52,'逐实例对比'!$H$4:$H$52,"OPTIMAL",'逐实例对比'!$N$4:$N$52,"OPTIMAL"),"")

Sheet 逐实例对比
A1: Concorde / HKMST / NEWHKMST 逐实例精确求解对比
A2: 实例 | D2: Concorde | H2: HKMST | N2: NEWHKMST
A3: 序号 | B3: 实例名 | C3: 顶点数 | D3: 状态 | E3: 求解结果 | F3: 运行时间(s) | G3: B&B节点数 | H3: 状态 | I3: 求解结果 | J3: 运行时间(s) | K3: 创建节点 | L3: 展开节点 | M3: 时间提升 vs Concorde | N3: 状态 | O3: 求解结果 | P3: 运行时间(s) | Q3: 创建节点 | R3: 展开节点 | S3: 时间提升 vs Concorde | T3: 时间提升 vs HKMST | U3: 分支减少 vs HKMST
A4: 1 | B4: data/classic/tsplib/burma14.tsp | C4: 14 | D4: OPTIMAL | E4: 3323 | F4: 0.020787418 | G4: 1 | H4: OPTIMAL | I4: 3323 | J4: 0.006457584 | K4: 1 | L4: 0 | M4: =IF(AND(D4="OPTIMAL",H4="OPTIMAL",F4>0),(F4-J4)/F4,"") | N4: OPTIMAL | O4: 3323 | P4: 0.0054409727 | Q4: 1 | R4: 0 | S4: =IF(AND(D4="OPTIMAL",N4="OPTIMAL",F4>0),(F4-P4)/F4,"") | T4: =IF(AND(H4="OPTIMAL",N4="OPTIMAL",J4>0),(J4-P4)/J4,"") | U4: =IF(AND(H4="OPTIMAL",N4="OPTIMAL",K4>0),(K4-Q4)/K4,"")
A5: 2 | B5: data/classic/tsplib/ulysses16.tsp | C5: 16 | D5: OPTIMAL | E5: 6859 | F5: 0.042184776 | G5: 1 | H5: OPTIMAL | I5: 6859 | J5: 0.014860943 | K5: 1 | L5: 0 | M5: =IF(AND(D5="OPTIMAL",H5="OPTIMAL",F5>0),(F5-J5)/F5,"") | N5: OPTIMAL | O5: 6859 | P5: 0.019424353 | Q5: 1 | R5: 0 | S5: =IF(AND(D5="OPTIMAL",N5="OPTIMAL",F5>0),(F5-P5)/F5,"") | T5: =IF(AND(H5="OPTIMAL",N5="OPTIMAL",J5>0),(J5-P5)/J5,"") | U5: =IF(AND(H5="OPTIMAL",N5="OPTIMAL",K5>0),(K5-Q5)/K5,"")
A6: 3 | B6: data/classic/tsplib/gr17.tsp | C6: 17 | D6: OPTIMAL | E6: 2085 | F6: 0.025793843 | G6: 1 | H6: OPTIMAL | I6: 2085 | J6: 0.010473488 | K6: 1 | L6: 0 | M6: =IF(AND(D6="OPTIMAL",H6="OPTIMAL",F6>0),(F6-J6)/F6,"") | N6: OPTIMAL | O6: 2085 | P6: 0.014960205 | Q6: 1 | R6: 0 | S6: =IF(AND(D6="OPTIMAL",N6="OPTIMAL",F6>0),(F6-P6)/F6,"") | T6: =IF(AND(H6="OPTIMAL",N6="OPTIMAL",J6>0),(J6-P6)/J6,"") | U6: =IF(AND(H6="OPTIMAL",N6="OPTIMAL",K6>0),(K6-Q6)/K6,"")
A7: 4 | B7: data/classic/tsplib/gr21.tsp | C7: 21 | D7: OPTIMAL | E7: 2707 | F7: 0.012801802 | G7: 1 | H7: OPTIMAL | I7: 2707 | J7: 0.010881804 | K7: 1 | L7: 0 | M7: =IF(AND(D7="OPTIMAL",H7="OPTIMAL",F7>0),(F7-J7)/F7,"") | N7: OPTIMAL | O7: 2707 | P7: 0.0059256032 | Q7: 1 | R7: 0 | S7: =IF(AND(D7="OPTIMAL",N7="OPTIMAL",F7>0),(F7-P7)/F7,"") | T7: =IF(AND(H7="OPTIMAL",N7="OPTIMAL",J7>0),(J7-P7)/J7,"") | U7: =IF(AND(H7="OPTIMAL",N7="OPTIMAL",K7>0),(K7-Q7)/K7,"")
A8: 5 | B8: data/classic/tsplib/gr24.tsp | C8: 24 | D8: OPTIMAL | E8: 1272 | F8: 0.023833286 | G8: 1 | H8: OPTIMAL | I8: 1272 | J8: 0.014801573 | K8: 1 | L8: 0 | M8: =IF(AND(D8="OPTIMAL",H8="OPTIMAL",F8>0),(F8-J8)/F8,"") | N8: OPTIMAL | O8: 1272 | P8: 0.015200539 | Q8: 1 | R8: 0 | S8: =IF(AND(D8="OPTIMAL",N8="OPTIMAL",F8>0),(F8-P8)/F8,"") | T8: =IF(AND(H8="OPTIMAL",N8="OPTIMAL",J8>0),(J8-P8)/J8,"") | U8: =IF(AND(H8="OPTIMAL",N8="OPTIMAL",K8>0),(K8-Q8)/K8,"")
A9: 6 | B9: data/classic/tsplib/fri26.tsp | C9: 26 | D9: OPTIMAL | E9: 937 | F9: 0.028426396 | G9: 1 | H9: OPTIMAL | I9: 937 | J9: 0.0098843351 | K9: 1 | L9: 0 | M9: =IF(AND(D9="OPTIMAL",H9="OPTIMAL",F9>0),(F9-J9)/F9,"") | N9: OPTIMAL | O9: 937 | P9: 0.012324883 | Q9: 1 | R9: 0 | S9: =IF(AND(D9="OPTIMAL",N9="OPTIMAL",F9>0),(F9-P9)/F9,"") | T9: =IF(AND(H9="OPTIMAL",N9="OPTIMAL",J9>0),(J9-P9)/J9,"") | U9: =IF(AND(H9="OPTIMAL",N9="OPTIMAL",K9>0),(K9-Q9)/K9,"")
A10: 7 | B10: data/classic/tsplib/bayg29.tsp | C10: 29 | D10: OPTIMAL | E10: 1610 | F10: 0.025282271 | G10: 1 | H10: OPTIMAL | I10: 1610 | J10: 0.021558216 | K10: 3 | L10: 3 | M10: =IF(AND(D10="OPTIMAL",H10="OPTIMAL",F10>0),(F10-J10)/F10,"") | N10: OPTIMAL | O10: 1610 | P10: 0.018735034 | Q10: 3 | R10: 3 | S10: =IF(AND(D10="OPTIMAL",N10="OPTIMAL",F10>0),(F10-P10)/F10,"") | T10: =IF(AND(H10="OPTIMAL",N10="OPTIMAL",J10>0),(J10-P10)/J10,"") | U10: =IF(AND(H10="OPTIMAL",N10="OPTIMAL",K10>0),(K10-Q10)/K10,"")
A11: 8 | B11: data/classic/tsplib/bays29.tsp | C11: 29 | D11: OPTIMAL | E11: 2020 | F11: 0.034718346 | G11: 1 | H11: OPTIMAL | I11: 2020 | J11: 0.016532734 | K11: 15 | L11: 11 | M11: =IF(AND(D11="OPTIMAL",H11="OPTIMAL",F11>0),(F11-J11)/F11,"") | N11: OPTIMAL | O11: 2020 | P11: 0.020772088 | Q11: 12 | R11: 7 | S11: =IF(AND(D11="OPTIMAL",N11="OPTIMAL",F11>0),(F11-P11)/F11,"") | T11: =IF(AND(H11="OPTIMAL",N11="OPTIMAL",J11>0),(J11-P11)/J11,"") | U11: =IF(AND(H11="OPTIMAL",N11="OPTIMAL",K11>0),(K11-Q11)/K11,"")
A12: 9 | B12: data/classic/national/wi29.tsp | C12: 29 | D12: OPTIMAL | E12: 27603 | F12: 0.040418899 | G12: 1 | H12: OPTIMAL | I12: 27603 | J12: 0.016047288 | K12: 1 | L12: 0 | M12: =IF(AND(D12="OPTIMAL",H12="OPTIMAL",F12>0),(F12-J12)/F12,"") | N12: OPTIMAL | O12: 27603 | P12: 0.013314866 | Q12: 1 | R12: 0 | S12: =IF(AND(D12="OPTIMAL",N12="OPTIMAL",F12>0),(F12-P12)/F12,"") | T12: =IF(AND(H12="OPTIMAL",N12="OPTIMAL",J12>0),(J12-P12)/J12,"") | U12: =IF(AND(H12="OPTIMAL",N12="OPTIMAL",K12>0),(K12-Q12)/K12,"")
A13: 10 | B13: data/classic/national/dj38.tsp | C13: 38 | D13: OPTIMAL | E13: 6656 | F13: 0.034308918 | G13: 1 | H13: OPTIMAL | I13: 6656 | J13: 0.021264892 | K13: 1 | L13: 0 | M13: =IF(AND(D13="OPTIMAL",H13="OPTIMAL",F13>0),(F13-J13)/F13,"") | N13: OPTIMAL | O13: 6656 | P13: 0.014045939 | Q13: 1 | R13: 0 | S13: =IF(AND(D13="OPTIMAL",N13="OPTIMAL",F13>0),(F13-P13)/F13,"") | T13: =IF(AND(H13="OPTIMAL",N13="OPTIMAL",J13>0),(J13-P13)/J13,"") | U13: =IF(AND(H13="OPTIMAL",N13="OPTIMAL",K13>0),(K13-Q13)/K13,"")
A14: 11 | B14: data/classic/tsplib/dantzig42.tsp | C14: 42 | D14: OPTIMAL | E14: 699 | F14: 0.043804053 | G14: 1 | H14: OPTIMAL | I14: 699 | J14: 0.029688084 | K14: 12 | L14: 6 | M14: =IF(AND(D14="OPTIMAL",H14="OPTIMAL",F14>0),(F14-J14)/F14,"") | N14: OPTIMAL | O14: 699 | P14: 0.027552165 | Q14: 7 | R14: 3 | S14: =IF(AND(D14="OPTIMAL",N14="OPTIMAL",F14>0),(F14-P14)/F14,"") | T14: =IF(AND(H14="OPTIMAL",N14="OPTIMAL",J14>0),(J14-P14)/J14,"") | U14: =IF(AND(H14="OPTIMAL",N14="OPTIMAL",K14>0),(K14-Q14)/K14,"")
A15: 12 | B15: data/classic/tsplib/swiss42.tsp | C15: 42 | D15: OPTIMAL | E15: 1273 | F15: 0.028971946 | G15: 1 | H15: OPTIMAL | I15: 1273 | J15: 0.024252234 | K15: 8 | L15: 4 | M15: =IF(AND(D15="OPTIMAL",H15="OPTIMAL",F15>0),(F15-J15)/F15,"") | N15: OPTIMAL | O15: 1273 | P15: 0.022043746 | Q15: 5 | R15: 3 | S15: =IF(AND(D15="OPTIMAL",N15="OPTIMAL",F15>0),(F15-P15)/F15,"") | T15: =IF(AND(H15="OPTIMAL",N15="OPTIMAL",J15>0),(J15-P15)/J15,"") | U15: =IF(AND(H15="OPTIMAL",N15="OPTIMAL",K15>0),(K15-Q15)/K15,"")
... A23: 20 | B23: data/classic/tsplib/eil76.tsp | C23: 76 | D23: OPTIMAL | E23: 538 | F23: 0.055488518 | G23: 1 | H23: OPTIMAL | I23: 538 | J23: 0.5863875 | K23: 132106 | L23: 105325 | M23: =IF(AND(D23="OPTIMAL",H23="OPTIMAL",F23>0),(F23-J23)/F23,"") | N23: OPTIMAL | O23: 538 | P23: 0.28649615 | Q23: 707 | R23: 248 | S23: =IF(AND(D23="OPTIMAL",N23="OPTIMAL",F23>0),(F23-P23)/F23,"") | T23: =IF(AND(H23="OPTIMAL",N23="OPTIMAL",J23>0),(J23-P23)/J23,"") | U23: =IF(AND(H23="OPTIMAL",N23="OPTIMAL",K23>0),(K23-Q23)/K23,"")
A24: 21 | B24: data/classic/tsplib/pr76.tsp | C24: 76 | D24: OPTIMAL | E24: 108159 | F24: 0.2005256 | G24: 1 | H24: TIMEOUT | J24: 1800 | M24: =IF(AND(D24="OPTIMAL",H24="OPTIMAL",F24>0),(F24-J24)/F24,"") | N24: TIMEOUT | P24: 1800 | S24: =IF(AND(D24="OPTIMAL",N24="OPTIMAL",F24>0),(F24-P24)/F24,"") | T24: =IF(AND(H24="OPTIMAL",N24="OPTIMAL",J24>0),(J24-P24)/J24,"") | U24: =IF(AND(H24="OPTIMAL",N24="OPTIMAL",K24>0),(K24-Q24)/K24,"")
A25: 22 | B25: data/classic/tsplib/gr96.tsp | C25: 96 | D25: OPTIMAL | E25: 55209 | F25: 0.22968503 | G25: 1 | H25: OPTIMAL | I25: 55209 | J25: 7.9173782 | K25: 2490722 | L25: 1672187 | M25: =IF(AND(D25="OPTIMAL",H25="OPTIMAL",F25>0),(F25-J25)/F25,"") | N25: OPTIMAL | O25: 55209 | P25: 5.4391172 | Q25: 553254 | R25: 387439 | S25: =IF(AND(D25="OPTIMAL",N25="OPTIMAL",F25>0),(F25-P25)/F25,"") | T25: =IF(AND(H25="OPTIMAL",N25="OPTIMAL",J25>0),(J25-P25)/J25,"") | U25: =IF(AND(H25="OPTIMAL",N25="OPTIMAL",K25>0),(K25-Q25)/K25,"")
A26: 23 | B26: data/classic/tsplib/rat99.tsp | C26: 99 | D26: OPTIMAL | E26: 1211 | F26: 1.1220329 | G26: 1 | H26: OPTIMAL | I26: 1211 | J26: 0.45007456 | K26: 91741 | L26: 67911 | M26: =IF(AND(D26="OPTIMAL",H26="OPTIMAL",F26>0),(F26-J26)/F26,"") | N26: OPTIMAL | O26: 1211 | P26: 0.60667261 | Q26: 1257 | R26: 478 | S26: =IF(AND(D26="OPTIMAL",N26="OPTIMAL",F26>0),(F26-P26)/F26,"") | T26: =IF(AND(H26="OPTIMAL",N26="OPTIMAL",J26>0),(J26-P26)/J26,"") | U26: =IF(AND(H26="OPTIMAL",N26="OPTIMAL",K26>0),(K26-Q26)/K26,"")
A27: 24 | B27: data/classic/tsplib/kroA100.tsp | C27: 100 | D27: OPTIMAL | E27: 21282 | F27: 0.091786541 | G27: 1 | H27: OPTIMAL | I27: 21282 | J27: 810.15215 | K27: 192614325 | L27: 146674028 | M27: =IF(AND(D27="OPTIMAL",H27="OPTIMAL",F27>0),(F27-J27)/F27,"") | N27: OPTIMAL | O27: 21282 | P27: 706.88059 | Q27: 172105550 | R27: 131023964 | S27: =IF(AND(D27="OPTIMAL",N27="OPTIMAL",F27>0),(F27-P27)/F27,"") | T27: =IF(AND(H27="OPTIMAL",N27="OPTIMAL",J27>0),(J27-P27)/J27,"") | U27: =IF(AND(H27="OPTIMAL",N27="OPTIMAL",K27>0),(K27-Q27)/K27,"")
A28: 25 | B28: data/classic/tsplib/kroB100.tsp | C28: 100 | D28: OPTIMAL | E28: 22141 | F28: 0.1910104 | G28: 1 | H28: TIMEOUT | J28: 1800 | M28: =IF(AND(D28="OPTIMAL",H28="OPTIMAL",F28>0),(F28-J28)/F28,"") | N28: TIMEOUT | P28: 1800 | S28: =IF(AND(D28="OPTIMAL",N28="OPTIMAL",F28>0),(F28-P28)/F28,"") | T28: =IF(AND(H28="OPTIMAL",N28="OPTIMAL",J28>0),(J28-P28)/J28,"") | U28: =IF(AND(H28="OPTIMAL",N28="OPTIMAL",K28>0),(K28-Q28)/K28,"")
A29: 26 | B29: data/classic/tsplib/kroC100.tsp | C29: 100 | D29: OPTIMAL | E29: 20749 | F29: 0.11494717 | G29: 1 | H29: OPTIMAL | I29: 20749 | J29: 40.26342 | K29: 11756617 | L29: 8463763 | M29: =IF(AND(D29="OPTIMAL",H29="OPTIMAL",F29>0),(F29-J29)/F29,"") | N29: OPTIMAL | O29: 20749 | P29: 33.535929 | Q29: 8892308 | R29: 6305937 | S29: =IF(AND(D29="OPTIMAL",N29="OPTIMAL",F29>0),(F29-P29)/F29,"") | T29: =IF(AND(H29="OPTIMAL",N29="OPTIMAL",J29>0),(J29-P29)/J29,"") | U29: =IF(AND(H29="OPTIMAL",N29="OPTIMAL",K29>0),(K29-Q29)/K29,"")
A30: 27 | B30: data/classic/tsplib/kroD100.tsp | C30: 100 | D30: OPTIMAL | E30: 21294 | F30: 0.14972636 | G30: 1 | H30: OPTIMAL | I30: 21294 | J30: 451.93376 | K30: 129214031 | L30: 90688415 | M30: =IF(AND(D30="OPTIMAL",H30="OPTIMAL",F30>0),(F30-J30)/F30,"") | N30: OPTIMAL | O30: 21294 | P30: 218.54705 | Q30: 63405303 | R30: 44593789 | S30: =IF(AND(D30="OPTIMAL",N30="OPTIMAL",F30>0),(F30-P30)/F30,"") | T30: =IF(AND(H30="OPTIMAL",N30="OPTIMAL",J30>0),(J30-P30)/J30,"") | U30: =IF(AND(H30="OPTIMAL",N30="OPTIMAL",K30>0),(K30-Q30)/K30,"")
A31: 28 | B31: data/classic/tsplib/kroE100.tsp | C31: 100 | D31: OPTIMAL | E31: 22068 | F31: 0.24494147 | G31: 1 | H31: TIMEOUT | J31: 1800 | M31: =IF(AND(D31="OPTIMAL",H31="OPTIMAL",F31>0),(F31-J31)/F31,"") | N31: TIMEOUT | P31: 1800 | S31: =IF(AND(D31="OPTIMAL",N31="OPTIMAL",F31>0),(F31-P31)/F31,"") | T31: =IF(AND(H31="OPTIMAL",N31="OPTIMAL",J31>0),(J31-P31)/J31,"") | U31: =IF(AND(H31="OPTIMAL",N31="OPTIMAL",K31>0),(K31-Q31)/K31,"")
A32: 29 | B32: data/classic/tsplib/rd100.tsp | C32: 100 | D32: OPTIMAL | E32: 7910 | F32: 0.082716016 | G32: 1 | H32: OPTIMAL | I32: 7910 | J32: 2.0531828 | K32: 525879 | L32: 350903 | M32: =IF(AND(D32="OPTIMAL",H32="OPTIMAL",F32>0),(F32-J32)/F32,"") | N32: OPTIMAL | O32: 7910 | P32: 1.1156228 | Q32: 59691 | R32: 40713 | S32: =IF(AND(D32="OPTIMAL",N32="OPTIMAL",F32>0),(F32-P32)/F32,"") | T32: =IF(AND(H32="OPTIMAL",N32="OPTIMAL",J32>0),(J32-P32)/J32,"") | U32: =IF(AND(H32="OPTIMAL",N32="OPTIMAL",K32>0),(K32-Q32)/K32,"")
A33: 30 | B33: data/classic/tsplib/eil101.tsp | C33: 101 | D33: OPTIMAL | E33: 629 | F33: 0.08875088 | G33: 1 | H33: OPTIMAL | I33: 629 | J33: 12.239017 | K33: 3763318 | L33: 2747059 | M33: =IF(AND(D33="OPTIMAL",H33="OPTIMAL",F33>0),(F33-J33)/F33,"") | N33: OPTIMAL | O33: 629 | P33: 1.0659177 | Q33: 1254 | R33: 421 | S33: =IF(AND(D33="OPTIMAL",N33="OPTIMAL",F33>0),(F33-P33)/F33,"") | T33: =IF(AND(H33="OPTIMAL",N33="OPTIMAL",J33>0),(J33-P33)/J33,"") | U33: =IF(AND(H33="OPTIMAL",N33="OPTIMAL",K33>0),(K33-Q33)/K33,"")
A34: 31 | B34: data/classic/tsplib/lin105.tsp | C34: 105 | D34: OPTIMAL | E34: 14379 | F34: 0.083049038 | G34: 1 | H34: OPTIMAL | I34: 14379 | J34: 0.17135262 | K34: 348 | L34: 225 | M34: =IF(AND(D34="OPTIMAL",H34="OPTIMAL",F34>0),(F34-J34)/F34,"") | N34: OPTIMAL | O34: 14379 | P34: 0.18792438 | Q34: 74 | R34: 28 | S34: =IF(AND(D34="OPTIMAL",N34="OPTIMAL",F34>0),(F34-P34)/F34,"") | T34: =IF(AND(H34="OPTIMAL",N34="OPTIMAL",J34>0),(J34-P34)/J34,"") | U34: =IF(AND(H34="OPTIMAL",N34="OPTIMAL",K34>0),(K34-Q34)/K34,"")
A35: 32 | B35: data/classic/tsplib/pr107.tsp | C35: 107 | D35: OPTIMAL | E35: 44303 | F35: 0.1422189 | G35: 1 | H35: TIMEOUT | J35: 1800 | M35: =IF(AND(D35="OPTIMAL",H35="OPTIMAL",F35>0),(F35-J35)/F35,"") | N35: TIMEOUT | P35: 1800 | S35: =IF(AND(D35="OPTIMAL",N35="OPTIMAL",F35>0),(F35-P35)/F35,"") | T35: =IF(AND(H35="OPTIMAL",N35="OPTIMAL",J35>0),(J35-P35)/J35,"") | U35: =IF(AND(H35="OPTIMAL",N35="OPTIMAL",K35>0),(K35-Q35)/K35,"")
A36: 33 | B36: data/classic/tsplib/gr120.tsp | C36: 120 | D36: OPTIMAL | E36: 6942 | F36: 0.1724096 | G36: 1 | H36: TIMEOUT | J36: 1800 | M36: =IF(AND(D36="OPTIMAL",H36="OPTIMAL",F36>0),(F36-J36)/F36,"") | N36: TIMEOUT | P36: 1800 | S36: =IF(AND(D36="OPTIMAL",N36="OPTIMAL",F36>0),(F36-P36)/F36,"") | T36: =IF(AND(H36="OPTIMAL",N36="OPTIMAL",J36>0),(J36-P36)/J36,"") | U36: =IF(AND(H36="OPTIMAL",N36="OPTIMAL",K36>0),(K36-Q36)/K36,"")
A37: 34 | B37: data/classic/tsplib/pr124.tsp | C37: 124 | D37: OPTIMAL | E37: 59030 | F37: 0.44735806 | G37: 1 | H37: OPTIMAL | I37: 59030 | J37: 3.6067607 | K37: 660814 | L37: 487141 | M37: =IF(AND(D37="OPTIMAL",H37="OPTIMAL",F37>0),(F37-J37)/F37,"") | N37: OPTIMAL | O37: 59030 | P37: 7.4574696 | Q37: 395730 | R37: 296198 | S37: =IF(AND(D37="OPTIMAL",N37="OPTIMAL",F37>0),(F37-P37)/F37,"") | T37: =IF(AND(H37="OPTIMAL",N37="OPTIMAL",J37>0),(J37-P37)/J37,"") | U37: =IF(AND(H37="OPTIMAL",N37="OPTIMAL",K37>0),(K37-Q37)/K37,"")
A38: 35 | B38: data/classic/tsplib/bier127.tsp | C38: 127 | D38: OPTIMAL | E38: 118282 | F38: 0.19664316 | G38: 1 | H38: TIMEOUT | J38: 1800 | M38: =IF(AND(D38="OPTIMAL",H38="OPTIMAL",F38>0),(F38-J38)/F38,"") | N38: TIMEOUT | P38: 1800 | S38: =IF(AND(D38="OPTIMAL",N38="OPTIMAL",F38>0),(F38-P38)/F38,"") | T38: =IF(AND(H38="OPTIMAL",N38="OPTIMAL",J38>0),(J38-P38)/J38,"") | U38: =IF(AND(H38="OPTIMAL",N38="OPTIMAL",K38>0),(K38-Q38)/K38,"")
A39: 36 | B39: data/classic/tsplib/ch130.tsp | C39: 130 | D39: OPTIMAL | E39: 6110 | F39: 0.19354412 | G39: 1 | H39: TIMEOUT | J39: 1800 | M39: =IF(AND(D39="OPTIMAL",H39="OPTIMAL",F39>0),(F39-J39)/F39,"") | N39: TIMEOUT | P39: 1800 | S39: =IF(AND(D39="OPTIMAL",N39="OPTIMAL",F39>0),(F39-P39)/F39,"") | T39: =IF(AND(H39="OPTIMAL",N39="OPTIMAL",J39>0),(J39-P39)/J39,"") | U39: =IF(AND(H39="OPTIMAL",N39="OPTIMAL",K39>0),(K39-Q39)/K39,"")
A40: 37 | B40: data/classic/tsplib/pr136.tsp | C40: 136 | D40: OPTIMAL | E40: 96772 | F40: 0.51489443 | G40: 1 | H40: TIMEOUT | J40: 1800 | M40: =IF(AND(D40="OPTIMAL",H40="OPTIMAL",F40>0),(F40-J40)/F40,"") | N40: TIMEOUT | P40: 1800 | S40: =IF(AND(D40="OPTIMAL",N40="OPTIMAL",F40>0),(F40-P40)/F40,"") | T40: =IF(AND(H40="OPTIMAL",N40="OPTIMAL",J40>0),(J40-P40)/J40,"") | U40: =IF(AND(H40="OPTIMAL",N40="OPTIMAL",K40>0),(K40-Q40)/K40,"")
A41: 38 | B41: data/classic/tsplib/gr137.tsp | C41: 137 | D41: OPTIMAL | E41: 69853 | F41: 0.33577058 | G41: 1 | H41: OPTIMAL | I41: 69853 | J41: 312.99065 | K41: 23991715 | L41: 16170127 | M41: =IF(AND(D41="OPTIMAL",H41="OPTIMAL",F41>0),(F41-J41)/F41,"") | N41: OPTIMAL | O41: 69853 | P41: 319.62511 | Q41: 24087201 | R41: 16259899 | S41: =IF(AND(D41="OPTIMAL",N41="OPTIMAL",F41>0),(F41-P41)/F41,"") | T41: =IF(AND(H41="OPTIMAL",N41="OPTIMAL",J41>0),(J41-P41)/J41,"") | U41: =IF(AND(H41="OPTIMAL",N41="OPTIMAL",K41>0),(K41-Q41)/K41,"")
A42: 39 | B42: data/classic/tsplib/pr144.tsp | C42: 144 | D42: OPTIMAL | E42: 58537 | F42: 0.25897668 | G42: 1 | H42: TIMEOUT | J42: 1800 | M42: =IF(AND(D42="OPTIMAL",H42="OPTIMAL",F42>0),(F42-J42)/F42,"") | N42: TIMEOUT | P42: 1800 | S42: =IF(AND(D42="OPTIMAL",N42="OPTIMAL",F42>0),(F42-P42)/F42,"") | T42: =IF(AND(H42="OPTIMAL",N42="OPTIMAL",J42>0),(J42-P42)/J42,"") | U42: =IF(AND(H42="OPTIMAL",N42="OPTIMAL",K42>0),(K42-Q42)/K42,"")
A43: 40 | B43: data/classic/tsplib/ch150.tsp | C43: 150 | D43: OPTIMAL | E43: 6528 | F43: 0.33793501 | G43: 1 | H43: TIMEOUT | J43: 1800 | M43: =IF(AND(D43="OPTIMAL",H43="OPTIMAL",F43>0),(F43-J43)/F43,"") | N43: TIMEOUT | P43: 1800 | S43: =IF(AND(D43="OPTIMAL",N43="OPTIMAL",F43>0),(F43-P43)/F43,"") | T43: =IF(AND(H43="OPTIMAL",N43="OPTIMAL",J43>0),(J43-P43)/J43,"") | U43: =IF(AND(H43="OPTIMAL",N43="OPTIMAL",K43>0),(K43-Q43)/K43,"")
A44: 41 | B44: data/classic/tsplib/kroA150.tsp | C44: 150 | D44: OPTIMAL | E44: 26524 | F44: 0.46448314 | G44: 1 | H44: TIMEOUT | J44: 1800 | M44: =IF(AND(D44="OPTIMAL",H44="OPTIMAL",F44>0),(F44-J44)/F44,"") | N44: TIMEOUT | P44: 1800 | S44: =IF(AND(D44="OPTIMAL",N44="OPTIMAL",F44>0),(F44-P44)/F44,"") | T44: =IF(AND(H44="OPTIMAL",N44="OPTIMAL",J44>0),(J44-P44)/J44,"") | U44: =IF(AND(H44="OPTIMAL",N44="OPTIMAL",K44>0),(K44-Q44)/K44,"")
A45: 42 | B45: data/classic/tsplib/kroB150.tsp | C45: 150 | D45: OPTIMAL | E45: 26130 | F45: 0.45467943 | G45: 1 | H45: TIMEOUT | J45: 1800 | M45: =IF(AND(D45="OPTIMAL",H45="OPTIMAL",F45>0),(F45-J45)/F45,"") | N45: TIMEOUT | P45: 1800 | S45: =IF(AND(D45="OPTIMAL",N45="OPTIMAL",F45>0),(F45-P45)/F45,"") | T45: =IF(AND(H45="OPTIMAL",N45="OPTIMAL",J45>0),(J45-P45)/J45,"") | U45: =IF(AND(H45="OPTIMAL",N45="OPTIMAL",K45>0),(K45-Q45)/K45,"")
A46: 43 | B46: data/classic/tsplib/pr152.tsp | C46: 152 | D46: OPTIMAL | E46: 73682 | F46: 0.86977196 | G46: 1 | H46: TIMEOUT | J46: 1800 | M46: =IF(AND(D46="OPTIMAL",H46="OPTIMAL",F46>0),(F46-J46)/F46,"") | N46: TIMEOUT | P46: 1800 | S46: =IF(AND(D46="OPTIMAL",N46="OPTIMAL",F46>0),(F46-P46)/F46,"") | T46: =IF(AND(H46="OPTIMAL",N46="OPTIMAL",J46>0),(J46-P46)/J46,"") | U46: =IF(AND(H46="OPTIMAL",N46="OPTIMAL",K46>0),(K46-Q46)/K46,"")
A47: 44 | B47: data/classic/tsplib/u159.tsp | C47: 159 | D47: OPTIMAL | E47: 42080 | F47: 0.11267022 | G47: 1 | H47: TIMEOUT | J47: 1800 | M47: =IF(AND(D47="OPTIMAL",H47="OPTIMAL",F47>0),(F47-J47)/F47,"") | N47: OPTIMAL | O47: 42080 | P47: 481.81948 | Q47: 24067676 | R47: 17654159 | S47: =IF(AND(D47="OPTIMAL",N47="OPTIMAL",F47>0),(F47-P47)/F47,"") | T47: =IF(AND(H47="OPTIMAL",N47="OPTIMAL",J47>0),(J47-P47)/J47,"") | U47: =IF(AND(H47="OPTIMAL",N47="OPTIMAL",K47>0),(K47-Q47)/K47,"")
...

Sheet 运行配置
A1: 实验运行配置
A2: 项目 | B2: 值 | C2: 说明
A3: 生成时间 | B3: 2026-08-07T08:16:29+00:00 | C3: 本地时区
A4: 实例数量 | B4: 49 | C4: 每个实例在逐实例表中占一行
A5: 顶点限制 | B5: n < 200 | C5: 默认仅测试小于200顶点
A6: 单次超时 | B6: 1800 | C6: 秒/算法/实例
A7: 并行实例数 | B7: 6 | C7: 同一实例的三种算法仍串行
A8: 单实例运行顺序 | B8: Concorde -> HKMST -> NEWHKMST | C8: 与 compare_strategies.py 的执行方式一致
A9: 重复次数 | B9: 1 | C9: 运行时间取中位数
A10: Concorde seed | B10: 123 | C10: 固定随机种子
A11: Concorde | B11: /home/wj/code/TSP/concorde/TSP/concorde | C11: ff9a290ccfd0a933f25a27cfbcac57062d096489c6aac1791318f5b0adeee3c6
A12: HKMST | B12: /home/wj/code/TSP/solver/HKMST/tsp_bb | C12: 13ddc36c66bdbce2ad430db95ce30dc31153c682258d1d830d117660a0d796d5
A13: HKMST参数 | B13: (无额外参数)
A14: NEWHKMST | B14: /home/wj/code/TSP/solver/NEWHKMST/tsp_bb | C14: 3a8bf08fbc455c803c427ad556f9453c623444059f031a7e4dd734759d0d80e4
A15: NEWHKMST参数 | B15: --hk-ascent polyak --hk-potential-update subtree-adaptive --hk-update-depth 2 --hk-update-gap-ratio 0.02 --hk-update-iterations 16 --hk-update-budget 5000 | C15: 持久子树势更新策略
A16: 缓存文件 | B16: /home/wj/code/TSP/docs/hkmst-newhkmst-comparison-cache.json | C16: 二进制或参数变化时自动失效
